<?xml version="1.0" ?>
<!-- =================================================================================== -->
<!-- |    This document was autogenerated by xacro from tortoisebot_simple.xacro       | -->
<!-- |    EDITING THIS FILE BY HAND IS NOT RECOMMENDED                                 | -->
<!-- =================================================================================== -->
<robot name="tortoisebot_simple">
  <!-- <xacro:property name="standard_friction" value="100.0" />
<xacro:property name="wheel_friction" value="1000.0" />
<xacro:property name="caster_friction" value="0.1" /> -->
  <!--  ##########  WHEEL FRICTION  ##########  -->
  <gazebo reference="wheel_left">
    <mu1>1.0</mu1>
    <mu2>1.0</mu2>
    <kp>500000.0</kp>
    <kd>10.0</kd>
    <minDepth>0.001</minDepth>
  </gazebo>
  <gazebo reference="wheel_right">
    <mu1>1.0</mu1>
    <mu2>1.0</mu2>
    <kp>500000.0</kp>
    <kd>10.0</kd>
    <minDepth>0.001</minDepth>
  </gazebo>
  <!--  ##########  CASTER FRICTION  ##########  -->
  <gazebo reference="castor_wheel">
    <mu1>0.1</mu1>
    <mu2>0.1</mu2>
  </gazebo>
  <!--  ##########  STANDARD FRICTION  ##########  -->
  <gazebo reference="base_link">
    <mu1>0.2</mu1>
    <mu2>0.2</mu2>
    <gravity>true</gravity>
  </gazebo>
  <gazebo reference="lidar">
    <mu1>0.2</mu1>
    <mu2>0.2</mu2>
  </gazebo>
  <gazebo reference="camera_link">
    <mu1>0.2</mu1>
    <mu2>0.2</mu2>
  </gazebo>
  <gazebo reference="camera_holder">
    <mu1>0.2</mu1>
    <mu2>0.2</mu2>
  </gazebo>
  <!-- Differential drive plugin for gazebo -->
  <gazebo>
    <plugin filename="libgazebo_ros_diff_drive.so" name="diff_drive_ttb">
      <ros>
        <!-- <namespace>/demo</namespace> -->
      </ros>
      <!-- wheels -->
      <left_joint>wheel_left_joint</left_joint>
      <right_joint>wheel_right_joint</right_joint>
      <!-- kinematics -->
      <wheel_separation>0.17186</wheel_separation>
      <wheel_diameter>0.065</wheel_diameter>
      <!-- limits -->
      <max_wheel_torque>20</max_wheel_torque>
      <max_wheel_acceleration>1.0</max_wheel_acceleration>
      <!-- output -->
      <publish_odom>true</publish_odom>
      <publish_odom_tf>true</publish_odom_tf>
      <publish_wheel_tf>false</publish_wheel_tf>
      <odometry_frame>odom</odometry_frame>
      <robot_base_frame>base_link</robot_base_frame>
    </plugin>
  </gazebo>
  <!--  ##########  LIDAR PLUGIN  ##########  -->
  <gazebo reference="lidar">
    <sensor name="ydlidar" type="ray">
      <always_on>true</always_on>
      <visualize>false</visualize>
      <update_rate>10</update_rate>
      <ray>
        <scan>
          <horizontal>
            <samples>720</samples>
            <resolution>1.000000</resolution>
            <min_angle>-3.14</min_angle>
            <max_angle>3.14</max_angle>
          </horizontal>
        </scan>
        <range>
          <min>0.05</min>
          <max>20.0</max>
          <resolution>0.015000</resolution>
        </range>
        <noise>
          <type>gaussian</type>
          <mean>0.0</mean>
          <stddev>0.01</stddev>
        </noise>
      </ray>
      <plugin filename="libgazebo_ros_ray_sensor.so" name="ttb_lidar">
        <ros>
          <remapping>~/out:=scan</remapping>
        </ros>
        <output_type>sensor_msgs/LaserScan</output_type>
        <frame_name>lidar</frame_name>
      </plugin>
    </sensor>
  </gazebo>
  <!--  ##########  CAMERA PLUGIN  ##########  -->
  <!-- camera -->
  <gazebo reference="camera_link">
    <sensor name="camera" type="depth">
      <update_rate>30.0</update_rate>
      <camera name="camera">
        <horizontal_fov>0.9337511</horizontal_fov>
        <image>
          <width>410</width>
          <height>308</height>
          <format>R8G8B8</format>
        </image>
        <clip>
          <near>0.002</near>
          <far>300</far>
        </clip>
        <noise>
          <type>gaussian</type>
          <mean>0.0</mean>
          <stddev>0.007</stddev>
        </noise>
      </camera>
      <plugin filename="libgazebo_ros_camera.so" name="camera_controller_pi">
        <alwaysOn>true</alwaysOn>
        <updateRate>0.0</updateRate>
        <cameraName>/camera</cameraName>
        <imageTopicName>/raspicam_node/image</imageTopicName>
        <cameraInfoTopicName>camera_info</cameraInfoTopicName>
        <frameName>camera_link</frameName>
        <hackBaseline>0.07</hackBaseline>
        <distortionK1>0.0</distortionK1>
        <distortionK2>0.0</distortionK2>
        <distortionK3>0.0</distortionK3>
        <distortionT1>0.0</distortionT1>
        <distortionT2>0.0</distortionT2>
      </plugin>
    </sensor>
  </gazebo>
  <link name="base_link">
    <inertial>
      <origin rpy="0 0 0" xyz="-0.030635608127622015 -0.0004221703596385517 0.07737044666769882"/>
      <mass value="1.129162264280885"/>
      <inertia ixx="0.004045" ixy="-1.2e-05" ixz="-2.9e-05" iyy="0.003768" iyz="2e-05" izz="0.002249"/>
    </inertial>
    <visual>
      <origin rpy="0 0 0" xyz="0 0 0"/>
      <geometry>
        <mesh filename="file:///home/rishang/Desktop/ROS2/frosthack/install/tortoisebot_description/share/tortoisebot_description/models/meshes/base_link.dae" scale="0.001 0.001 0.001"/>
      </geometry>
    </visual>
    <collision>
      <origin rpy="0 0 0" xyz="0 0 0"/>
      <geometry>
        <mesh filename="file:///home/rishang/Desktop/ROS2/frosthack/install/tortoisebot_description/share/tortoisebot_description/models/meshes/base_link.dae" scale="0.001 0.001 0.001"/>
      </geometry>
    </collision>
  </link>
  <!-- Added by Rishang -->
  <link name="base_footprint"/>
  <joint name="base_link_to_base_footprint" type="fixed">
    <origin rpy="0 0 0" xyz="0 0 0"/>
    <parent link="base_link"/>
    <child link="base_footprint"/>
  </joint>
  <!-- mera bhang bhosda ends here -->
  <link name="wheel_left">
    <inertial>
      <origin rpy="0 0 0" xyz="-5.817360584857412e-08 0.008992666701213833 -2.8524983942262994e-07"/>
      <mass value="0.04355937082025941"/>
      <inertia ixx="1.9e-05" ixy="-0.0" ixz="-0.0" iyy="3.3e-05" iyz="0.0" izz="1.9e-05"/>
    </inertial>
    <visual>
      <origin rpy="0 0 0" xyz="0.000197 -0.0778 -0.032453"/>
      <geometry>
        <mesh filename="file:///home/rishang/Desktop/ROS2/frosthack/install/tortoisebot_description/share/tortoisebot_description/models/meshes/wheel_left.dae" scale="0.001 0.001 0.001"/>
      </geometry>
    </visual>
    <collision>
      <origin rpy="0 0 0" xyz="0.000197 -0.0778 -0.032453"/>
      <geometry>
        <mesh filename="file:///home/rishang/Desktop/ROS2/frosthack/install/tortoisebot_description/share/tortoisebot_description/models/meshes/wheel_left.dae" scale="0.001 0.001 0.001"/>
      </geometry>
    </collision>
  </link>
  <link name="wheel_right">
    <inertial>
      <origin rpy="0 0 0" xyz="1.1651486266691519e-09 -0.008992199795129496 -2.763726826629509e-07"/>
      <mass value="0.04355937082025929"/>
      <inertia ixx="1.9e-05" ixy="0.0" ixz="0.0" iyy="3.3e-05" iyz="0.0" izz="1.9e-05"/>
    </inertial>
    <visual>
      <origin rpy="0 0 0" xyz="-0.0001 0.0778 -0.032453"/>
      <geometry>
        <mesh filename="file:///home/rishang/Desktop/ROS2/frosthack/install/tortoisebot_description/share/tortoisebot_description/models/meshes/wheel_right.dae" scale="0.001 0.001 0.001"/>
      </geometry>
    </visual>
    <collision>
      <origin rpy="0 0 0" xyz="-0.0001 0.0778 -0.032453"/>
      <geometry>
        <mesh filename="file:///home/rishang/Desktop/ROS2/frosthack/install/tortoisebot_description/share/tortoisebot_description/models/meshes/wheel_right.dae" scale="0.001 0.001 0.001"/>
      </geometry>
    </collision>
  </link>
  <link name="lidar">
    <inertial>
      <origin rpy="0 0 0" xyz="1.6353780135647256e-10 -1.7329123482757136e-13 0.004356361811340997"/>
      <mass value="0.02603693115872038"/>
      <inertia ixx="6e-06" ixy="0.0" ixz="0.0" iyy="6e-06" iyz="-0.0" izz="1.2e-05"/>
    </inertial>
    <visual>
      <origin rpy="0 0 0" xyz="0.03275 0.0 -0.167"/>
      <geometry>
        <mesh filename="file:///home/rishang/Desktop/ROS2/frosthack/install/tortoisebot_description/share/tortoisebot_description/models/meshes/lidar.dae" scale="0.001 0.001 0.001"/>
      </geometry>
    </visual>
    <collision>
      <origin rpy="0 0 0" xyz="0.03275 0.0 -0.167"/>
      <geometry>
        <mesh filename="file:///home/rishang/Desktop/ROS2/frosthack/install/tortoisebot_description/share/tortoisebot_description/models/meshes/lidar.dae" scale="0.001 0.001 0.001"/>
      </geometry>
    </collision>
  </link>
  <link name="camera_link">
    <inertial>
      <origin rpy="0 0 0" xyz="0.0005000001639132029 -1.7004031399497072e-07 1.1512051351081354e-07"/>
      <mass value="3.746349259254909e-05"/>
      <inertia ixx="0.0" ixy="0.0" ixz="-0.0" iyy="0.0" iyz="0.0" izz="0.0"/>
    </inertial>
    <visual>
      <origin rpy="0 0 0" xyz="-0.05025 -1e-05 -0.133907"/>
      <geometry>
        <mesh filename="file:///home/rishang/Desktop/ROS2/frosthack/install/tortoisebot_description/share/tortoisebot_description/models/meshes/camera_link.dae" scale="0.001 0.001 0.001"/>
      </geometry>
    </visual>
    <collision>
      <origin rpy="0 0 0" xyz="-0.05025 -1e-05 -0.133907"/>
      <geometry>
        <mesh filename="file:///home/rishang/Desktop/ROS2/frosthack/install/tortoisebot_description/share/tortoisebot_description/models/meshes/camera_link.dae" scale="0.001 0.001 0.001"/>
      </geometry>
    </collision>
  </link>
  <link name="camera_holder">
    <inertial>
      <origin rpy="0 0 0" xyz="0.012956561190815237 4.623703165912345e-06 0.0017885934065832443"/>
      <mass value="0.003607670102548807"/>
      <inertia ixx="0.0" ixy="-0.0" ixz="-0.0" iyy="0.0" iyz="-0.0" izz="0.0"/>
    </inertial>
    <visual>
      <origin rpy="0 0 0" xyz="-0.03125 0.0 -0.131063"/>
      <geometry>
        <mesh filename="file:///home/rishang/Desktop/ROS2/frosthack/install/tortoisebot_description/share/tortoisebot_description/models/meshes/camera_holder.dae" scale="0.001 0.001 0.001"/>
      </geometry>
    </visual>
    <collision>
      <origin rpy="0 0 0" xyz="-0.03125 0.0 -0.131063"/>
      <geometry>
        <mesh filename="file:///home/rishang/Desktop/ROS2/frosthack/install/tortoisebot_description/share/tortoisebot_description/models/meshes/camera_holder.dae" scale="0.001 0.001 0.001"/>
      </geometry>
    </collision>
  </link>
  <link name="castor_wheel">
    <inertial>
      <origin rpy="0 0 0" xyz="2.5326962749261384e-14 4.504651888394023e-14 -0.0017582044401419582"/>
      <mass value="0.0033567272126794434"/>
      <inertia ixx="0.0" ixy="0.0" ixz="0.0" iyy="0.0" iyz="0.0" izz="0.0"/>
    </inertial>
    <visual>
      <origin rpy="0 0 0" xyz="0.0767 0.0 -0.0049"/>
      <geometry>
        <mesh filename="file:///home/rishang/Desktop/ROS2/frosthack/install/tortoisebot_description/share/tortoisebot_description/models/meshes/castor_wheel.dae" scale="0.001 0.001 0.001"/>
      </geometry>
    </visual>
    <collision>
      <origin rpy="0 0 0" xyz="0.0767 0.0 -0.0049"/>
      <geometry>
        <mesh filename="file:///home/rishang/Desktop/ROS2/frosthack/install/tortoisebot_description/share/tortoisebot_description/models/meshes/castor_wheel.dae" scale="0.001 0.001 0.001"/>
      </geometry>
    </collision>
  </link>
  <link name="imu_link"/>
  <joint name="wheel_left_joint" type="continuous">
    <origin rpy="0 0 0" xyz="-0.000197 0.0778 0.032453"/>
    <parent link="base_link"/>
    <child link="wheel_left"/>
    <axis xyz="0.0 1.0 0.0"/>
  </joint>
  <joint name="wheel_right_joint" type="continuous">
    <origin rpy="0 0 0" xyz="0.0001 -0.0778 0.032453"/>
    <parent link="base_link"/>
    <child link="wheel_right"/>
    <axis xyz="0.0 1.0 0.0"/>
  </joint>
  <joint name="lidar_joint" type="fixed">
    <origin rpy="0 0 0" xyz="-0.03275 0.0 0.167"/>
    <parent link="base_link"/>
    <child link="lidar"/>
  </joint>
  <joint name="camera_sensor_joint" type="fixed">
    <origin rpy="0 0 0" xyz="0.019 1e-05 0.002844"/>
    <parent link="camera_holder"/>
    <child link="camera_link"/>
  </joint>
  <!-- <link name="camera_not_optical_link" /> -->
  <joint name="camera_optical_joint" type="fixed">
    <parent link="camera_link"/>
    <child link="camera_link_optical"/>
    <origin rpy="-1.5708 0 -1.5708" xyz="0 0 0"/>
  </joint>
  <link name="camera_link_optical"/>
  <joint name="camera_tilt_joint" type="fixed">
    <origin rpy="0 0 0" xyz="0.03125 0.0 0.131063"/>
    <parent link="base_link"/>
    <child link="camera_holder"/>
  </joint>
  <joint name="castor_joint" type="fixed">
    <origin rpy="0 0 0" xyz="-0.0767 0.0 0.0049"/>
    <parent link="base_link"/>
    <child link="castor_wheel"/>
  </joint>
  <joint name="imu_joint" type="fixed">
    <origin rpy="0 0 0" xyz="0.0 0.0 0.11"/>
    <parent link="base_link"/>
    <child link="imu_link"/>
  </joint>
</robot>
